<?xml version="1.0" encoding="utf-8"?>
<!-- This URDF was automatically created by SolidWorks to URDF Exporter! Originally created by Stephen Brawner (brawner@gmail.com) 
     Commit Version: 1.5.1-0-g916b5db  Build Version: 1.5.7152.31018
     For more information, please see http://wiki.ros.org/sw_urdf_exporter -->
<robot
  name="URDF">
  <link
    name="base_link">
    <inertial>
      <origin
        xyz="-4.38422850545704E-17 -1.45040801108932E-16 2.92309912661133E-17"
        rpy="0 0 0" />
      <mass
        value="0.772800000000001" />
      <inertia
        ixx="0.00668137120000001"
        ixy="4.92776609352633E-33"
        ixz="0"
        iyy="0.0115355216"
        iyz="-3.99130395075699E-19"
        izz="0.0067378496" />
    </inertial>
    <visual>
      <origin
        xyz="0 0 0"
        rpy="0 0 0" />
      <geometry>
        <mesh
          filename="package://URDF/meshes/base_link.STL" />
      </geometry>
      <material
        name="">
        <color
          rgba="0.792156862745098 0.819607843137255 0.933333333333333 1" />
      </material>
    </visual>
    <collision>
      <origin
        xyz="0 0 0"
        rpy="0 0 0" />
      <geometry>
        <mesh
          filename="package://URDF/meshes/base_link.STL" />
      </geometry>
    </collision>
  </link>
  <link
    name="left_comp">
    <inertial>
      <origin
        xyz="-0.0646447944006999 2.59629400186522E-17 3.58527119395351E-18"
        rpy="0 0 0" />
      <mass
        value="0.329184" />
      <inertia
        ixx="0.002396417184"
        ixy="-7.93335534705613E-20"
        ixz="4.15243661696412E-19"
        iyy="0.00251953318651969"
        iyz="3.20053593725935E-19"
        izz="0.000695389666519684" />
    </inertial>
    <visual>
      <origin
        xyz="0 0 0"
        rpy="0 0 0" />
      <geometry>
        <mesh
          filename="package://URDF/meshes/left_comp.STL" />
      </geometry>
      <material
        name="">
        <color
          rgba="0.792156862745098 0.819607843137255 0.933333333333333 1" />
      </material>
    </visual>
    <collision>
      <origin
        xyz="0 0 0"
        rpy="0 0 0" />
      <geometry>
        <mesh
          filename="package://URDF/meshes/left_comp.STL" />
      </geometry>
    </collision>
  </link>
  <joint
    name="left_prism"
    type="prismatic">
    <origin
      xyz="-0.14279 0 0"
      rpy="1.5708 0 0" />
    <parent
      link="base_link" />
    <child
      link="left_comp" />
    <axis
      xyz="1 0 0" />
    <limit
      lower="-0.1"
      upper="0"
      effort="0"
      velocity="0.007" />
  </joint>
  <link
    name="right_comp">
    <inertial>
      <origin
        xyz="0.0646447944006999 2.60516302226131E-17 1.89022067613556E-17"
        rpy="0 0 0" />
      <mass
        value="0.329184" />
      <inertia
        ixx="0.002396417184"
        ixy="1.05858877303928E-19"
        ixz="4.0251550176018E-19"
        iyy="0.00251953318651968"
        iyz="7.67976538843899E-20"
        izz="0.000695389666519685" />
    </inertial>
    <visual>
      <origin
        xyz="0 0 0"
        rpy="0 0 0" />
      <geometry>
        <mesh
          filename="package://URDF/meshes/right_comp.STL" />
      </geometry>
      <material
        name="">
        <color
          rgba="0.792156862745098 0.819607843137255 0.933333333333333 1" />
      </material>
    </visual>
    <collision>
      <origin
        xyz="0 0 0"
        rpy="0 0 0" />
      <geometry>
        <mesh
          filename="package://URDF/meshes/right_comp.STL" />
      </geometry>
    </collision>
  </link>
  <joint
    name="right_prism"
    type="prismatic">
    <origin
      xyz="0.13782 0 0"
      rpy="1.5708 0 0" />
    <parent
      link="base_link" />
    <child
      link="right_comp" />
    <axis
      xyz="1 0 0" />
    <limit
      lower="0"
      upper="0.1"
      effort="0"
      velocity="0.007" />
  </joint>
</robot>